Workbook

Sheet Resumen
A1: RESUMEN — huella de lo que va en cada puesto (sin circulación)
A2: Suma de las huellas con medida. Los ítems en rojo sin medida no suman: el total crece cuando se completan.
A3: Puesto | B3: Huella de lo que va adentro (m²)
A4: MANUALES
A5: 4. Corte de disco y embutido (cúpula y fondo) · 1 máq. · 2 turnos | B5: =Manuales!F5 -> 12.02
A6: 5. Preparación de cuello · 2 máq. · 2 turnos | B6: =Manuales!F13 -> 0
A7: 7. Soldadura del cuello a la cúpula · 1 máq. · 2 turnos | B7: =Manuales!F16 -> 4.03
A8: 8. Cilindrado · 1 máq. · 1 turno | B8: =Manuales!F21 -> 3.25
A9: 9. Soldadura longitudinal — 2,5 a 10 kg · 1 máq. · 2 turnos | B9: =Manuales!F25 -> 7.27
A10: 10. Soldadura longitudinal TIG — 1 kg · 1 máq. · 2 turnos | B10: =Manuales!F30 -> 1.32
A11: 11. Encastre de fondo · 1 máq. · 2 turnos | B11: =Manuales!F33 -> 6.288575
A12: 12. Bordoneado · 1 máq. · 2 turnos | B12: =Manuales!F39 -> 1.75
A13: 13. Soldadura circunferencial de cúpula y fondo · 2 máq. · 2 turnos | B13: =Manuales!F43 -> 10.31
A14: 14. Control de calidad — Espesor · 1 máq. · 1 turno | B14: =Manuales!F49 -> 0
A15: 17. Granallado · 1 máq. · 2 turnos | B15: =Manuales!F52 -> 6.76
A16: 18. Detección de defectos · 1 máq. · 2 turnos | B16: =Manuales!F56 -> 0
A17: 19. Corrección de defectos · 1 máq. · 1 turno | B17: =Manuales!F59 -> 0
A18: 20. Pintura en polvo + horno · 1 máq. · 2 turnos | B18: =Manuales!F62 -> 35.54
A19: 21. Carga de polvo · 1 máq. · 1 turno | B19: =Manuales!F69 -> 4.1062
A20: 22. Ensamblaje · 1 máq. · 2 turnos | B20: =Manuales!F74 -> 3.395
A21: 23. Presurización · 1 máq. · 1 turno | B21: =Manuales!F79 -> 3.07
A22: 24. Control de calidad — Ensayo de pérdidas · 1 máq. · 1 turno | B22: =Manuales!F84 -> 3.43
A23: 25. Etiquetado · 1 máq. · 1 turno | B23: =Manuales!F89 -> 3.3625
A24: 26. Embalaje y paletizado · 2 máq. · 2 turnos | B24: =Manuales!F94 -> 8.8084
A25: Total Manuales | B25: =SUM(B5:B24) -> 114.71067
A27: CARROS
A28: 3. Cilindrado · 1 máq. · 1 turno | B28: =Carros!F5 -> 9.2592429
A29: 4. Punteo del cuerpo · 1 máq. · 1 turno | B29: =Carros!F9 -> 0.57518571
A30: 5. Soldadura longitudinal · 1 máq. · 1 turno | B30: =Carros!F14 -> 3.0036
A31: 6. Soldadura de cupla en la cúpula · 1 máq. · 1 turno | B31: =Carros!F18 -> 0.47164286
A32: 7. Armado y soldadura circunferencial · 1 máq. · 1 turno | B32: =Carros!F22 -> 2.4176143
A33: 8. Soldadura de accesorios · 1 máq. · 1 turno | B33: =Carros!F27 -> 0.39882857
A34: 8.1. Fabricación de accesorios · 1 máq. · 1 turno | B34: =Carros!F32 -> 0
A35: 11. Pulmón de despacho y carga a pintura · 1 máq. · 1 turno | B35: =Carros!F35 -> 12.65
A36: 12. Recepción de pintados y cambio de juego · 1 máq. · 1 turno | B36: =Carros!F38 -> 12.65
A37: 13 B. Carga de polvo y presurización · 1 máq. · 1 turno | B37: =Carros!F41 -> 0.3162
A38: 13 A-C / 15. Montaje, manga, precinto y etiquetado · 1 máq. · 1 turno | B38: =Carros!F44 -> 0
A39: 14-17. Calidad: pérdidas, inspección final, liberación y ensayos de lote · 1 máq. · 1 turno | B39: =Carros!F47 -> 0
A40: Total Carros | B40: =SUM(B28:B39) -> 41.742314
A42: RECARGAS
...

Sheet Compartidos
A1: PUESTOS COMPARTIDOS — los usan manuales y carros
A2: Gris = puesto y la suma de las huellas de lo que va adentro (sin circulación). Medidas solo de las cotizaciones y de los Excel de Fran (Balanceo y Pulmones). Rojo = no está en esas fuentes.
A4: Puesto / ítem | B4: Lo usa | C4: Cant. | D4: Ancho (m) | E4: Largo (m) | F4: Alto (m) | G4: Huella (m²) | H4: Medidas internas / uso | I4: Fuente | J4: A confirmar
A5: CORTE — guillotina 1 (franjas) · Manuales 2 y Carros 2 | G5: =SUM(G6:G6) -> 6.3826 | I5: Manuales: Balanceo-FLAMA2035 › Carga R35 (máq.) y S35 (turnos) · Carros: Carga M75 (máq.) y N75 (turnos)
A6: Guillotina 1 Ermaksan HGS 2600-6 | B6: Los dos | C6: 1 | D6: 1.88 | E6: 3.395 | F6: 1.55 | G6: =C6*D6*E6 -> 6.3826 | H6: corte 2.600 mm, chapa hasta 6 mm, 5.000 kg | I6: Máquina: Balanceo-FLAMA2035 › Lotes A22 · medidas: exapro.com y resale.info n.º 164666861 (ERMAK HGS 2600 × 6: 3.395 × 1.880 × 1.550 mm) | J6: Medidas de avisos de venta del mismo modelo: confirmar con Ermaksan. Sin el tope trasero
A8: CORTE — guillotina 2 (piezas) · Manuales 3 y Carros 2 | G8: =SUM(G9:G11) -> 9.182 | I8: Manuales: Balanceo-FLAMA2035 › Carga R36 (máq.) y S36 (turnos) · Carros: Carga M75 (máq.) y N75 (turnos)
A9: Guillotina 2 QC12Y 6 × 2500 | B9: Los dos | C9: 1 | D9: 1.62 | E9: 3.1 | F9: 1.6 | G9: =C9*D9*E9 -> 5.022 | H9: corte 2.500 mm, chapa hasta 6 mm, 4.800 kg | I9: Máquina: Balanceo-FLAMA2035 › Lotes A23 · medidas: goldsupplier.com/provide/p106252035.html (QC12Y-6X2500: 3.100 × 1.620 × 1.600 mm) | J9: Medidas de la ficha del fabricante chino (LIWANG): confirmar con el proveedor. Sin el tope trasero
A10: Mesa elevadora 2 = pulmón de franjas | B10: Los dos | C10: 1 | D10: 1.3 | E10: 2.5 | F10: 0.35 | G10: =C10*D10*E10 -> 3.25 | H10: mesa de tijera 3.000 kg; 0,35 m cerrada, 1,93 m abierta | I10: Internet: Workplace Products, mesas de tijera de 3.000 kg (2.500 × 1.300 mm) · Balanceo-FLAMA2035 › Parametros B38 (2 hojas) · PULMONES-FLAMA2035 › Pulmones H6 (90 franjas) | J10: La hoja más grande es de 1.500 × 3.000 (MP-FLAMA2035 › Resumen A24): la plataforma de 2,5 × 1,3 m le queda corta. Confirmar
A11: Carro porta-bandejas: desarrollos → marcado del cuerpo | B11: Los dos | C11: 1 | D11: 0.7 | E11: 1.3 | F11: a confirmar | G11: =C11*D11*E11 -> 0.91 | H11: 3 bandejas 1.200 × 600, hasta 450 kg; espera en el origen | I11: PULMONES-FLAMA2035 › Parametros A42:B42 (lugar de 1 m² del carro de 1,3 × 0,7 m) y B37 (3 bandejas) · cantidad: Pulmones S7 (¿puede parar el que entrega?: Z7) | J11: Alto del carro (3 niveles a la altura del estante)
A13: MARCADO DEL CUERPO · Manuales 6 y Carros 2.1 | G13: =SUM(G14:G15) -> 4.035 | I13: Manuales: Balanceo-FLAMA2035 › Carga R39 (máq.) y S39 (turnos) · Carros: Carga M76 (máq.) y N76 (turnos)
A14: Marcadora | B14: Los dos | C14: 2 | D14: 0.75 | E14: 1.25 | F14: 1.2 | G14: =C14*D14*E14 -> 1.875 | H14: Firesafer FS-0001 (roll code), 600–700 pzas/h | I14: Cotización Firesafer (ítem 26, coding machine); medidas del catálogo | J14: La cotización trae 1. Balanceo: 2 puestos (uno para el 1 kg). Falta definir el método (micropercusión o láser)
A15: Estante: desarrollos (pulmón) | B15: Los dos | C15: 3 | D15: 0.6 | E15: 1.2 | F15: 2 | G15: =C15*D15*E15 -> 2.16 | H15: Estante: pilas por modelo sobre bandejas; máx. 1505 u en 15 bandejas o cajones | I15: PULMONES-FLAMA2035 › Parametros B7 (frente 1.200), B8 (fondo 600) y B9 (alto 2.000) · módulos: Pulmones O7 · máximo: H7 · bandejas: N7
A17: PRUEBA HIDRÁULICA · Manuales 15 y Carros 9 | G17: =SUM(G18:G20) -> 3.87 | I17: Manuales: Balanceo-FLAMA2035 › Carga R48 (máq.) y S48 (turnos) · Carros: Carga M84 (máq.) y N84 (turnos)
A18: Máquina de PH Yukon M-000200 (manuales) | B18: Los dos | C18: 2 | D18: 0.4 | E18: 0.95 | F18: 1.05 | G18: =C18*D18*E18 -> 0.76 | H18: sin mesa | I18: Cotización Yukon (Prueba Hidráulica) | J18: Falta el alto de la mesa. Alternativa Firesafer FS-0124 2,05 × 1,10 × 1,35
A19: Máquina de PH Yukon M-000200 (carros) | B19: Los dos | C19: 1 | D19: 0.4 | E19: 0.95 | F19: 1.05 | G19: =C19*D19*E19 -> 0.38 | H19: sin mesa | I19: Cotización Yukon (Prueba Hidráulica) | J19: Falta el alto de la mesa
A20: Carro porta-bandejas: cilindros mojados → secado | B20: Los dos | C20: 3 | D20: 0.7 | E20: 1.3 | F20: a confirmar | G20: =C20*D20*E20 -> 2.73 | H20: 3 bandejas 1.200 × 600, hasta 450 kg; espera en el origen | I20: PULMONES-FLAMA2035 › Parametros A42:B42 (lugar de 1 m² del carro de 1,3 × 0,7 m) y B37 (3 bandejas) · cantidad: Pulmones S17 (¿puede parar el que entrega?: Z17) | J20: Alto del carro (3 niveles a la altura del estante)
A22: SECADO · Manuales 16 y Carros 10 | G22: =SUM(G23:G25) -> 5.04 | I22: Manuales: Balanceo-FLAMA2035 › Carga R49 (máq.) y S49 (turnos) · Carros: Carga M85 (máq.) y N85 (turnos)
A23: Secadora de 4 bocas Firesafer FS-D4 (manuales) | B23: Los dos | C23: 4 | D23: 0.462 | E23: 1 | F23: 1.1 | G23: =C23*D23*E23 -> 1.848 | H23: seca 4 recipientes a la vez | I23: Catálogo Firesafer de service (FS-D4: 100 × 46,2 × 110 cm) | J23: No hay cotización de secado; se toma la del catálogo Firesafer. Balanceo pide 4 máquinas: con 4 bocas cada una, confirmar si alcanza con menos
A24: Secadora de 4 bocas Firesafer FS-D4 (carros) | B24: Los dos | C24: 1 | D24: 0.462 | E24: 1 | F24: 1.1 | G24: =C24*D24*E24 -> 0.462 | I24: Catálogo Firesafer de service (FS-D4) | J24: Confirmar que la lanza llegue al fondo de un carro de 100 kg
A25: Carro porta-bandejas: cilindros secos → granallado | B25: Los dos | C25: 3 | D25: 0.7 | E25: 1.3 | F25: a confirmar | G25: =C25*D25*E25 -> 2.73 | H25: 3 bandejas 1.200 × 600, hasta 450 kg; espera en el origen | I25: PULMONES-FLAMA2035 › Parametros A42:B42 (lugar de 1 m² del carro de 1,3 × 0,7 m) y B37 (3 bandejas) · cantidad: Pulmones S18 (¿puede parar el que entrega?: Z18) | J25: Alto del carro (3 niveles a la altura del estante)

Sheet Manuales
A1: MANUALES — lo que va dentro de cada puesto
A2: Gris = puesto y la suma de las huellas de lo que va adentro (sin circulación). Medidas solo de las cotizaciones y de los Excel de Fran (Balanceo y Pulmones). Rojo = no está en esas fuentes.
A4: Puesto / ítem | B4: Cant. | C4: Ancho (m) | D4: Largo (m) | E4: Alto (m) | F4: Huella (m²) | G4: Medidas internas / uso | H4: Fuente | I4: A confirmar
A5: 4. Corte de disco y embutido (cúpula y fondo) · 1 máq. · 2 turnos | F5: =SUM(F6:F11) -> 12.02 | H5: Balanceo-FLAMA2035 › Carga R37 (máq.) y S37 (turnos)
A6: Prensa Sangiacomo | B6: 1 | C6: 1.3 | D6: 1.6 | E6: 3.32 | F6: =B6*C6*D6 -> 2.08 | G6: Sangiacomo T130 R CE: 130 t, mesa 1.200 × 700 mm, 10.000 kg | H6: Máquina: Balanceo-FLAMA2035 › Lotes A42 · medidas: exapro.com/sp/sangiacomo-t130rce-19888 (1.600 × 1.300 × 3.320 mm) | I6: Fran no dice el modelo ni el tonelaje: se toma la T130 R. Confirmar modelo
A7: Desbobinador CENA TC-400 | B7: 1 | C7: 1 | D7: 1.2 | E7: 1.3 | F7: =B7*C7*D7 -> 1.2 | G7: fleje hasta 400 mm, rollo hasta Ø 1.200 y 1.500 kg | H7: Cotización CENA (desbobinador): 1.200 × 1.000 × 1.300 mm | I7: Elegido por el fleje más ancho (238,7 mm, MP-FLAMA2035 › Resumen A33) y el rollo más pesado (1.181 kg, Resumen B31): el TC-300 llega a 1.000 kg
A8: Enderezadora CENA SC-300 | B8: 1 | C8: 0.55 | D8: 0.8 | E8: 1.3 | F8: =B8*C8*D8 -> 0.44 | G8: fleje hasta 300 mm y 3 mm | H8: Cotización CENA (enderezadora): 800 × 550 × 1.300 mm | I8: Elegida por el fleje más ancho (238,7 mm) y el más grueso (2,0 mm), MP-FLAMA2035 › Resumen A33. El alimentador servo no trae medidas
A9: Rack de fondos y cúpulas (supermercado, pulmón) | B9: 2 | C9: 1.2 | D9: 2.7 | E9: a confirmar | F9: =B9*C9*D9 -> 6.48 | G9: vano de 2,7 m × 3 niveles, 3 pallets 1.200 × 800 por nivel; 17 pallets de 12 cajones | H9: PULMONES-FLAMA2035 › Parametros B56 (vano 2,7 m), B57 (fondo 1,2 m), B54 (3 niveles), B55 (3 pallets por nivel) · vanos: Equipos B12 · pallets: Equipos B13 | I9: Alto del rack (primer nivel a 400 mm, pallet de 1.045 mm de alto)
A10: Carro de 12 cajones: fondos | B10: 1 | C10: 0.7 | D10: 1.3 | E10: a confirmar | F10: =B10*C10*D10 -> 0.91 | G10: 4 niveles de 3 cajones 600 × 400 × 300 | H10: PULMONES-FLAMA2035 › Parametros B38 (12 cajones en 4 niveles); medidas = carro de A42 (1,3 × 0,7 m) · cantidad: Pulmones S10 | I10: Fran pide confirmar que el carro tenga 4 niveles de 3 cajones; si no, se pide igual al porta-bandejas (1,3 × 0,7 m) con 4 niveles. Alto del carro
A11: Carro de 12 cajones: cúpulas | B11: 1 | C11: 0.7 | D11: 1.3 | E11: a confirmar | F11: =B11*C11*D11 -> 0.91 | G11: 4 niveles de 3 cajones 600 × 400 × 300 | H11: PULMONES-FLAMA2035 › Parametros B38 (12 cajones en 4 niveles); medidas = carro de A42 (1,3 × 0,7 m) · cantidad: Pulmones S11 | I11: Fran pide confirmar que el carro tenga 4 niveles de 3 cajones; si no, se pide igual al porta-bandejas (1,3 × 0,7 m) con 4 niveles. Alto del carro
A13: 5. Preparación de cuello · 2 máq. · 2 turnos | F13: =SUM(F14:F14) -> 0 | H13: Balanceo-FLAMA2035 › Carga R38 (máq.) y S38 (turnos)
A14: Prensa de muesca del cuello | B14: 2 | C14: a confirmar | D14: a confirmar | E14: a confirmar | I14: No hay cotización en la carpeta para este puesto
A16: 7. Soldadura del cuello a la cúpula · 1 máq. · 2 turnos | F16: =SUM(F17:F19) -> 4.03 | H16: Balanceo-FLAMA2035 › Carga R40 (máq.) y S40 (turnos)
A17: Soldadora de cuello | B17: 1 | C17: 1.4 | D17: 1.2 | E17: 1.58 | F17: =B17*C17*D17 -> 1.68 | G17: Firesafer FS-HPM: plato divisor, 12 pzas/min | H17: Catálogo Firesafer (FS Cylinder Production) | I17: Está en el catálogo pero no en la cotización Firesafer. Confirmar el modelo
A18: Estante: cúpulas (pulmón) | B18: 2 | C18: 0.6 | D18: 1.2 | E18: 2 | F18: =B18*C18*D18 -> 1.44 | G18: Rack de pallets al lado de la prensa (la tanda) + estante en el puesto con la ola de mañana; máx. 6765 u en 80 bandejas o cajones | H18: PULMONES-FLAMA2035 › Parametros B7 (frente 1.200), B8 (fondo 600) y B9 (alto 2.000) · módulos: Pulmones O11 · máximo: H11 · bandejas: N11
A19: Carro de 12 cajones: cúpulas con cuello | B19: 1 | C19: 0.7 | D19: 1.3 | E19: a confirmar | F19: =B19*C19*D19 -> 0.91 | G19: 4 niveles de 3 cajones 600 × 400 × 300 | H19: PULMONES-FLAMA2035 › Parametros B38 (12 cajones en 4 niveles); medidas = carro de A42 (1,3 × 0,7 m) · cantidad: Pulmones S13 | I19: Fran pide confirmar que el carro tenga 4 niveles de 3 cajones; si no, se pide igual al porta-bandejas (1,3 × 0,7 m) con 4 niveles. Alto del carro
A21: 8. Cilindrado · 1 máq. · 1 turno | F21: =SUM(F22:F23) -> 3.25 | H21: Balanceo-FLAMA2035 › Carga R41 (máq.) y S41 (turnos)
A22: Roladora (cilindradora de manuales) | B22: 1 | C22: 1.3 | D22: 1.8 | E22: 1.25 | F22: =B22*C22*D22 -> 2.34 | G22: Firesafer FS-PM01: Ø 50–163 mm, 10 pzas/min | H22: Catálogo Firesafer (FS Cylinder Production); la cotización Firesafer cotiza 2 roladoras | I22: Hay 4 opciones: Firesafer FS-PM01 1,80 × 1,30 × 1,25 · Bästlein AK-BEND AS 70-10 1,70 × 0,70 × 1,10 · WMT OSTAS SM 700 × 76 1,30 × 0,80 × 1,30 · Getweld 2 rodillos (sin medidas). Se pone la más grande. Balanceo: 1 máquina; en Rueda se toman 2 (roladora propia del 1 kg)
A23: Carro porta-bandejas: virolas → soldadura longitudinal | B23: 1 | C23: 0.7 | D23: 1.3 | E23: a confirmar | F23: =B23*C23*D23 -> 0.91 | G23: 3 bandejas 1.200 × 600, hasta 450 kg; espera en el origen | H23: PULMONES-FLAMA2035 › Parametros A42:B42 (lugar de 1 m² del carro de 1,3 × 0,7 m) y B37 (3 bandejas) · cantidad: Pulmones S8 (¿puede parar el que entrega?: Z8) | I23: Alto del carro (3 niveles a la altura del estante)
A25: 9. Soldadura longitudinal — 2,5 a 10 kg · 1 máq. · 2 turnos | F25: =SUM(F26:F28) -> 7.27 | H25: Balanceo-FLAMA2035 › Carga R42 (máq.) y S42 (turnos)
A26: Soldadora longitudinal 2,5 a 10 kg | B26: 1 | C26: 1 | D26: 1.32 | E26: 1.8 | F26: =B26*C26*D26 -> 1.32 | G26: MIG, largo de soldadura hasta 500 mm (Getweld ZF-500) | H26: Cotización Getweld ZF-500; medidas: china.org.ru/product/1607235162 (ZF-500: 1.320, 1.000, 1.800 mm) | I26: La cotización no da medidas. La ficha de internet no rotula las columnas: confirmar largo × ancho × alto con Getweld
A27: Estante: virolas (pulmón) | B27: 7 | C27: 0.6 | D27: 1.2 | E27: 2 | F27: =B27*C27*D27 -> 5.04 | G27: Estante: parados en bandejas, un modelo por bandeja; máx. 607 u en 20 bandejas o cajones | H27: PULMONES-FLAMA2035 › Parametros B7 (frente 1.200), B8 (fondo 600) y B9 (alto 2.000) · módulos: Pulmones O8 · máximo: H8 · bandejas: N8
A28: Carro porta-bandejas: cuerpos soldados → encastre de fondo | B28: 1 | C28: 0.7 | D28: 1.3 | E28: a confirmar | F28: =B28*C28*D28 -> 0.91 | G28: 3 bandejas 1.200 × 600, hasta 450 kg; espera en el origen | H28: PULMONES-FLAMA2035 › Parametros A42:B42 (lugar de 1 m² del carro de 1,3 × 0,7 m) y B37 (3 bandejas) · cantidad: Pulmones S9 (¿puede parar el que entrega?: Z9) | I28: Pulmones da 2; propuesta 1 + soporte fijo para la bandeja en llenado (con tandas no hace falta el segundo). alto del carro (3 niveles a la altura del estante)
A30: 10. Soldadura longitudinal TIG — 1 kg · 1 máq. · 2 turnos | F30: =SUM(F31:F31) -> 1.32 | H30: Balanceo-FLAMA2035 › Carga R43 (máq.) y S43 (turnos)
A31: Soldadora longitudinal TIG 1 kg | B31: 1 | C31: 1 | D31: 1.32 | E31: 1.8 | F31: =B31*C31*D31 -> 1.32 | G31: equivalente: soldadora longitudinal ZF-500 | H31: Cotización Firesafer (TIG); medidas: china.org.ru/product/1607235162 | I31: Firesafer no da medidas; se toma la misma longitudinal ZF-500. Confirmar
A33: 11. Encastre de fondo · 1 máq. · 2 turnos | F33: =SUM(F34:F37) -> 6.288575 | H33: Balanceo-FLAMA2035 › Carga R44 (máq.) y S44 (turnos)
A34: Prensa de encastre de fondo 30 t | B34: 1 | C34: 1.315 | D34: 0.805 | E34: 2.12 | F34: =B34*C34*D34 -> 1.058575 | G34: equivalente: prensa de taller motorizada 30 t Promac 30-TON-MH2 | H34: Internet: ficha Promac 30-TON-MH2 (2.120 × 1.315 × 805 mm) | I34: La cotización (Del Fabro 30 t) es solo un link que no carga. La ficha no dice qué medida es cada eje: se toma el alto 2,12 m
A35: Estante: cuerpos soldados (pulmón) | B35: 4 | C35: 0.6 | D35: 1.2 | E35: 2 | F35: =B35*C35*D35 -> 2.88 | G35: Estante: parados en bandejas, un modelo por bandeja; máx. 405 u en 10 bandejas o cajones | H35: PULMONES-FLAMA2035 › Parametros B7 (frente 1.200), B8 (fondo 600) y B9 (alto 2.000) · módulos: Pulmones O9 · máximo: H9 · bandejas: N9
A36: Estante: fondos (pulmón) | B36: 2 | C36: 0.6 | D36: 1.2 | E36: 2 | F36: =B36*C36*D36 -> 1.44 | G36: Rack de pallets al lado de la prensa (la tanda) + estante en el puesto con la ola de mañana; máx. 6609 u en 65 bandejas o cajones | H36: PULMONES-FLAMA2035 › Parametros B7 (frente 1.200), B8 (fondo 600) y B9 (alto 2.000) · módulos: Pulmones O10 · máximo: H10 · bandejas: N10
A37: Carro porta-bandejas: cuerpos con fondo → bordoneado | B37: 1 | C37: 0.7 | D37: 1.3 | E37: a confirmar | F37: =B37*C37*D37 -> 0.91 | G37: 3 bandejas 1.200 × 600, hasta 450 kg; espera en el origen | H37: PULMONES-FLAMA2035 › Parametros A42:B42 (lugar de 1 m² del carro de 1,3 × 0,7 m) y B37 (3 bandejas) · cantidad: Pulmones S14 (¿puede parar el que entrega?: Z14) | I37: Pulmones da 2; propuesta 1 + soporte fijo para la bandeja en llenado (con tandas no hace falta el segundo). alto del carro (3 niveles a la altura del estante)
A39: 12. Bordoneado · 1 máq. · 2 turnos | F39: =SUM(F40:F41) -> 1.75 | H39: Balanceo-FLAMA2035 › Carga R45 (máq.) y S45 (turnos)
A40: Bordoneadora | B40: 1 | C40: 0.7 | D40: 1.2 | E40: 1.2 | F40: =B40*C40*D40 -> 0.84 | G40: equivalente: bordoneadora motorizada AK-BEND AKM 250 (2,5 mm) | H40: Internet: resale.info n.º 165720938 (AKM 250: 1,2 × 0,7 × 1,2 m) | I40: Las cotizaciones Prinzing SME 80/3P y Pilman SWM-400 no dan medidas y no se encontraron en internet
A41: Carro porta-bandejas: cuerpos bordoneados → soldadura circunferencial de cúpula y fondo | B41: 1 | C41: 0.7 | D41: 1.3 | E41: a confirmar | F41: =B41*C41*D41 -> 0.91 | G41: 3 bandejas 1.200 × 600, hasta 450 kg; espera en el origen | H41: PULMONES-FLAMA2035 › Parametros A42:B42 (lugar de 1 m² del carro de 1,3 × 0,7 m) y B37 (3 bandejas) · cantidad: Pulmones S15 (¿puede parar el que entrega?: Z15) | I41: Alto del carro (3 niveles a la altura del estante)
A43: 13. Soldadura circunferencial de cúpula y fondo · 2 máq. · 2 turnos | F43: =SUM(F44:F47) -> 10.31 | H43: Balanceo-FLAMA2035 › Carga R46 (máq.) y S46 (turnos)
A44: Soldadora circunferencial | B44: 2 | C44: a confirmar | D44: a confirmar | E44: a confirmar | G44: Getweld ZNC250X2: Ø < 250 mm, 340 pzas/8 h | H44: Cotizaciones Getweld ZNC250X2, SC Welding PRO-WP150 y Firesafer | I44: Ninguna cotización de la carpeta da medidas y no se encontraron en internet. PRO-WP150: plato Ø 450 mm
A45: Estante: cúpulas con cuello (pulmón) | B45: 1 | C45: 0.6 | D45: 1.2 | E45: 2 | F45: =B45*C45*D45 -> 0.72 | G45: Estante de cajones al pie de la soldadura circunferencial; máx. 407 u en 9 bandejas o cajones | H45: PULMONES-FLAMA2035 › Parametros B7 (frente 1.200), B8 (fondo 600) y B9 (alto 2.000) · módulos: Pulmones O13 · máximo: H13 · bandejas: N13
A46: Estante: cuerpos bordoneados (pulmón) | B46: 7 | C46: 0.6 | D46: 1.2 | E46: 2 | F46: =B46*C46*D46 -> 5.04 | G46: Estante: parados en bandejas, un modelo por bandeja; máx. 691 u en 21 bandejas o cajones | H46: PULMONES-FLAMA2035 › Parametros B7 (frente 1.200), B8 (fondo 600) y B9 (alto 2.000) · módulos: Pulmones O15 · máximo: H15 · bandejas: N15
A47: Carro porta-bandejas: cilindros soldados → prueba hidráulica | B47: 5 | C47: 0.7 | D47: 1.3 | E47: a confirmar | F47: =B47*C47*D47 -> 4.55 | G47: 3 bandejas 1.200 × 600, hasta 450 kg; espera en el origen | H47: PULMONES-FLAMA2035 › Parametros A42:B42 (lugar de 1 m² del carro de 1,3 × 0,7 m) y B37 (3 bandejas) · cantidad: Pulmones S16 (¿puede parar el que entrega?: Z16) | I47: Alto del carro (3 niveles a la altura del estante)
A49: 14. Control de calidad — Espesor · 1 máq. · 1 turno | F49: =SUM(F50:F50) -> 0 | H49: Balanceo-FLAMA2035 › Carga R47 (máq.) y S47 (turnos)
A50: Medidor de espesores | B50: 1 | C50: a confirmar | D50: a confirmar | E50: a confirmar | I50: No hay cotización en la carpeta para este puesto
...

Sheet Carros
A1: CARROS — lo que va dentro de cada puesto
A2: Gris = puesto y la suma de las huellas de lo que va adentro (sin circulación). Medidas solo de las cotizaciones y de los Excel de Fran (Balanceo y Pulmones). Rojo = no está en esas fuentes.
A4: Puesto / ítem | B4: Cant. | C4: Ancho (m) | D4: Largo (m) | E4: Alto (m) | F4: Huella (m²) | G4: Medidas internas / uso | H4: Fuente | I4: A confirmar
A5: 3. Cilindrado · 1 máq. · 1 turno | F5: =SUM(F6:F7) -> 9.2592429 | H5: Balanceo-FLAMA2035 › Carga M77 (máq.) y N77 (turnos)
A6: Roladora de carros (6 × 1.500) | B6: 1 | C6: 1.21 | D6: 3.31 | E6: 1.33 | F6: =B6*C6*D6 -> 4.0051 | G6: equivalente: roladora W11-6×1500 | H6: Internet: goldsupplier.com/provide/p106252607.html, W11-6×1500 (331 × 121 × 133, en cm) | I6: No hay cotización. Se elige 6 × 1.500 porque la chapa de carros es de 4,75 × 1.500 (MP-FLAMA2035 › Resumen A26). Confirmar unidades
A7: Piso demarcado: cuerpos planos grabados (pulmón) | B7: 1 | E7: — | F7: =7.3558/1.4 -> 5.2541429 | G7: Sobre la mesa móvil de la guillotina, apilados (tanda de corte); máx. 52 recipientes; huella = m² de Pulmones ÷ 1,4 de circulación | H7: PULMONES-FLAMA2035 › Carros J6 (m²), H6 (máximo) e I6 (cómo espera)
A9: 4. Punteo del cuerpo · 1 máq. · 1 turno | F9: =SUM(F10:F12) -> 0.57518571 | H9: Balanceo-FLAMA2035 › Carga M78 (máq.) y N78 (turnos)
A10: Virador ProArc TR-0100 (motriz) | B10: 1 | C10: 0.32 | D10: 0.47 | E10: 0.334 | F10: =B10*C10*D10 -> 0.1504 | G10: 1 t; Ø 20–800 mm | H10: Internet: westermans.com, ProArc TR-0100 (motriz 470 × 320 × 334, loco 450 × 160 × 334 mm) | I10: No hay cotización: equivalente de 1 t. La distancia entre motriz y loco depende del largo del recipiente
A11: Virador ProArc TR-0100 (loco) | B11: 1 | C11: 0.16 | D11: 0.45 | E11: 0.334 | F11: =B11*C11*D11 -> 0.072 | H11: Internet: westermans.com, ProArc TR-0100
A12: Piso demarcado: virolas (pulmón) | B12: 1 | E12: — | F12: =0.4939/1.4 -> 0.35278571 | G12: Piso demarcado de 1,8 × 1,2 m al pie del punteo, paradas; máx. 2 recipientes; huella = m² de Pulmones ÷ 1,4 de circulación | H12: PULMONES-FLAMA2035 › Carros J7 (m²), H7 (máximo) e I7 (cómo espera)
A14: 5. Soldadura longitudinal · 1 máq. · 1 turno | F14: =SUM(F15:F16) -> 3.0036 | H14: Balanceo-FLAMA2035 › Carga M79 (máq.) y N79 (turnos)
A15: Soldadora longitudinal Dragon ZH-1300 | B15: 1 | C15: 1.14 | D15: 2.3 | E15: 1.8 | F15: =B15*C15*D15 -> 2.622 | G15: con mesa elevadora con rodillos; largo de soldadura 1.300 mm | H15: Proforma Dragon Welding BF26091611
A16: Chiller SDL-1000 | B16: 1 | C16: 0.53 | D16: 0.72 | E16: 0.87 | F16: =B16*C16*D16 -> 0.3816 | G16: medidas de embalaje | H16: Proforma Dragon Welding BF26091611 | I16: Son medidas del embalaje, no de la máquina
A18: 6. Soldadura de cupla en la cúpula · 1 máq. · 1 turno | F18: =SUM(F19:F20) -> 0.47164286 | H18: Balanceo-FLAMA2035 › Carga M80 (máq.) y N80 (turnos)
A19: Soldadora de cupla | B19: 1 | C19: a confirmar | D19: a confirmar | E19: a confirmar | I19: No hay cotización en la carpeta para este puesto
A20: Piso demarcado: cúpulas con cupla (pulmón) | B20: 1 | E20: — | F20: =0.6603/1.4 -> 0.47164286 | G20: En el carro canasto entre la soldadura de cupla y el armado; máx. 13 recipientes; huella = m² de Pulmones ÷ 1,4 de circulación | H20: PULMONES-FLAMA2035 › Carros J9 (m²), H9 (máximo) e I9 (cómo espera)
A22: 7. Armado y soldadura circunferencial · 1 máq. · 1 turno | F22: =SUM(F23:F25) -> 2.4176143 | H22: Balanceo-FLAMA2035 › Carga M81 (máq.) y N81 (turnos)
A23: Virador ProArc TR-0100 (motriz) | B23: 1 | C23: 0.32 | D23: 0.47 | E23: 0.334 | F23: =B23*C23*D23 -> 0.1504 | G23: 1 t; Ø 20–800 mm | H23: Internet: westermans.com, ProArc TR-0100 (motriz 470 × 320 × 334, loco 450 × 160 × 334 mm) | I23: No hay cotización: equivalente de 1 t. La distancia entre motriz y loco depende del largo del recipiente
A24: Virador ProArc TR-0100 (loco) | B24: 1 | C24: 0.16 | D24: 0.45 | E24: 0.334 | F24: =B24*C24*D24 -> 0.072 | H24: Internet: westermans.com, ProArc TR-0100
A25: Piso demarcado: cuerpos soldados (pulmón) | B25: 1 | E25: — | F25: =3.0733/1.4 -> 2.1952143 | G25: Piso demarcado al pie del armado (7), parados; máx. 11 recipientes; huella = m² de Pulmones ÷ 1,4 de circulación | H25: PULMONES-FLAMA2035 › Carros J8 (m²), H8 (máximo) e I8 (cómo espera)
A27: 8. Soldadura de accesorios · 1 máq. · 1 turno | F27: =SUM(F28:F30) -> 0.39882857 | H27: Balanceo-FLAMA2035 › Carga M82 (máq.) y N82 (turnos)
A28: Virador ProArc TR-0100 (motriz) | B28: 1 | C28: 0.32 | D28: 0.47 | E28: 0.334 | F28: =B28*C28*D28 -> 0.1504 | G28: 1 t; Ø 20–800 mm | H28: Internet: westermans.com, ProArc TR-0100 (motriz 470 × 320 × 334, loco 450 × 160 × 334 mm) | I28: No hay cotización: equivalente de 1 t. La distancia entre motriz y loco depende del largo del recipiente
A29: Virador ProArc TR-0100 (loco) | B29: 1 | C29: 0.16 | D29: 0.45 | E29: 0.334 | F29: =B29*C29*D29 -> 0.072 | H29: Internet: westermans.com, ProArc TR-0100
A30: Piso demarcado: cilindros cerrados (pulmón) | B30: 1 | E30: — | F30: =0.247/1.4 -> 0.17642857 | G30: Piso demarcado al pie de accesorios (8), parados; máx. 1 recipientes; huella = m² de Pulmones ÷ 1,4 de circulación | H30: PULMONES-FLAMA2035 › Carros J10 (m²), H10 (máximo) e I10 (cómo espera)
A32: 8.1. Fabricación de accesorios · 1 máq. · 1 turno | F32: =SUM(F33:F33) -> 0 | H32: Balanceo-FLAMA2035 › Carga M83 (máq.) y N83 (turnos)
A33: Equipos de fabricación de accesorios | B33: 1 | C33: a confirmar | D33: a confirmar | E33: a confirmar | I33: No hay cotización en la carpeta para este puesto
A35: 11. Pulmón de despacho y carga a pintura · 1 máq. · 1 turno | F35: =SUM(F36:F36) -> 12.65 | H35: Balanceo-FLAMA2035 › Carga M86 (máq.) y N86 (turnos)
A36: Piso demarcado: recipientes esperando la pintura (pulmón) | B36: 1 | E36: — | F36: =17.71/1.4 -> 12.65 | G36: Espera del pintor: piso demarcado junto al portón, parados con un taco atrás; máx. 29 recipientes; huella = m² de Pulmones ÷ 1,4 de circulación | H36: PULMONES-FLAMA2035 › Carros J11 (m²), H11 (máximo) e I11 (cómo espera)
A38: 12. Recepción de pintados y cambio de juego · 1 máq. · 1 turno | F38: =SUM(F39:F39) -> 12.65 | H38: Balanceo-FLAMA2035 › Carga M87 (máq.) y N87 (turnos)
A39: Piso demarcado: carros pintados (pulmón) | B39: 1 | E39: — | F39: =17.71/1.4 -> 12.65 | G39: Piso demarcado de pintados: sin ruedas, parados sobre un taco de madera; máx. 29 recipientes; huella = m² de Pulmones ÷ 1,4 de circulación | H39: PULMONES-FLAMA2035 › Carros J13 (m²), H13 (máximo) e I13 (cómo espera)
A41: 13 B. Carga de polvo y presurización · 1 máq. · 1 turno | F41: =SUM(F42:F42) -> 0.3162 | H41: Balanceo-FLAMA2035 › Carga M88 (máq.) y N88 (turnos)
A42: Cargadora de polvo Yukon M-000121 | B42: 1 | C42: 0.51 | D42: 0.62 | E42: 1.2 | F42: =B42*C42*D42 -> 0.3162 | H42: Cotización Yukon (Máquina de llenado)
A44: 13 A-C / 15. Montaje, manga, precinto y etiquetado · 1 máq. · 1 turno | F44: =SUM(F45:F45) -> 0 | H44: Balanceo-FLAMA2035 › Carga M89 (máq.) y N89 (turnos)
A45: Montaje, manga, precinto y etiquetado | B45: 1 | C45: a confirmar | D45: a confirmar | E45: a confirmar | I45: No hay cotización en la carpeta para este puesto
A47: 14-17. Calidad: pérdidas, inspección final, liberación y ensayos de lote · 1 máq. · 1 turno | F47: =SUM(F48:F48) -> 0 | H47: Balanceo-FLAMA2035 › Carga M90 (máq.) y N90 (turnos)
A48: Calidad: pérdidas, inspección final y ensayos de lote | B48: 1 | C48: a confirmar | D48: a confirmar | E48: a confirmar | I48: No hay cotización en la carpeta para este puesto

Sheet Recargas
A1: RECARGAS — lo que va dentro de cada puesto
A2: Gris = puesto y la suma de las huellas de lo que va adentro (sin circulación). Medidas solo de las cotizaciones y de los Excel de Fran (Balanceo y Pulmones). Rojo = no está en esas fuentes.
A4: Puesto / ítem | B4: Cant. | C4: Ancho (m) | D4: Largo (m) | E4: Alto (m) | F4: Huella (m²) | G4: Medidas internas / uso | H4: Fuente | I4: A confirmar
A5: R1. Recepción y registro · 2 máq. · 1 turno | F5: =SUM(F6:F7) -> 2.4 | H5: Balanceo-FLAMA2035 › Carga F104 (máq.) y G104 (turnos)
A6: Equipo de recepción y registro | B6: 2 | C6: a confirmar | D6: a confirmar | E6: a confirmar | I6: No hay cotización en la carpeta para este puesto
A7: Jaula en espera (pulmón) | B7: 2 | C7: 1 | D7: 1.2 | E7: a confirmar | F7: =B7*C7*D7 -> 2.4 | G7: 28 equipos por jaula; los equipos que se juntan = los que llegan por hora × las horas que pasa cada uno en el puesto (trabajo + ½ h de espera) | H7: Balanceo-FLAMA2035 › Carga M104 (jaulas) y L104 (equipos) · jaula 1,2 × 1,0 m y 28 equipos: Parametros A52:B52 | I7: Alto de la jaula
A9: R2. Inspección visual · 2 máq. · 2 turnos | F9: =SUM(F10:F11) -> 1.2 | H9: Balanceo-FLAMA2035 › Carga F105 (máq.) y G105 (turnos)
A10: Equipo de inspección visual | B10: 2 | C10: a confirmar | D10: a confirmar | E10: a confirmar | I10: No hay cotización en la carpeta para este puesto
A11: Jaula en espera (pulmón) | B11: 1 | C11: 1 | D11: 1.2 | E11: a confirmar | F11: =B11*C11*D11 -> 1.2 | G11: 28 equipos por jaula; los equipos que se juntan = los que llegan por hora × las horas que pasa cada uno en el puesto (trabajo + ½ h de espera) | H11: Balanceo-FLAMA2035 › Carga M105 (jaulas) y L105 (equipos) · jaula 1,2 × 1,0 m y 28 equipos: Parametros A52:B52 | I11: Alto de la jaula
A13: R3. Descarga ABC — ruta recuperable · 1 máq. · 2 turnos | F13: =SUM(F14:F15) -> 1.52 | H13: Balanceo-FLAMA2035 › Carga F106 (máq.) y G106 (turnos)
A14: Recuperadora / cargadora de polvo Firesafer FS-ZR01 | B14: 1 | C14: 0.4 | D14: 0.8 | E14: 1.35 | F14: =B14*C14*D14 -> 0.32 | G14: recupera y carga 1–12 kg | H14: Catálogo Firesafer de service (FS 2026 Service Lists) | I14: Opción por función: confirmar. Alternativa FS-SDP-1 sin medidas
A15: Jaula en espera (pulmón) | B15: 1 | C15: 1 | D15: 1.2 | E15: a confirmar | F15: =B15*C15*D15 -> 1.2 | G15: 28 equipos por jaula; los equipos que se juntan = los que llegan por hora × las horas que pasa cada uno en el puesto (trabajo + ½ h de espera) | H15: Balanceo-FLAMA2035 › Carga M106 (jaulas) y L106 (equipos) · jaula 1,2 × 1,0 m y 28 equipos: Parametros A52:B52 | I15: Alto de la jaula
A17: R4. Descarga a descarte (ABC, BC y Clase D) · 1 máq. · 1 turno | F17: =SUM(F18:F19) -> 1.2 | H17: Balanceo-FLAMA2035 › Carga F107 (máq.) y G107 (turnos)
A18: Equipo de descarga a descarte (abc, bc y clase d) | B18: 1 | C18: a confirmar | D18: a confirmar | E18: a confirmar | I18: No hay cotización en la carpeta para este puesto
A19: Jaula en espera (pulmón) | B19: 1 | C19: 1 | D19: 1.2 | E19: a confirmar | F19: =B19*C19*D19 -> 1.2 | G19: 28 equipos por jaula; los equipos que se juntan = los que llegan por hora × las horas que pasa cada uno en el puesto (trabajo + ½ h de espera) | H19: Balanceo-FLAMA2035 › Carga M107 (jaulas) y L107 (equipos) · jaula 1,2 × 1,0 m y 28 equipos: Parametros A52:B52 | I19: Alto de la jaula
A21: R5. Descarga y carga de agua / AFFF / sales K · 1 máq. · 1 turno | F21: =SUM(F22:F23) -> 1.548 | H21: Balanceo-FLAMA2035 › Carga F108 (máq.) y G108 (turnos)
A22: Cargadora de agua y espuma Firesafer FS-SJML01 | B22: 1 | C22: 0.58 | D22: 0.6 | E22: 0.95 | F22: =B22*C22*D22 -> 0.348 | H22: Catálogo Firesafer de service (FS 2026 Service Lists) | I22: Opción por función: confirmar
A23: Jaula en espera (pulmón) | B23: 1 | C23: 1 | D23: 1.2 | E23: a confirmar | F23: =B23*C23*D23 -> 1.2 | G23: 28 equipos por jaula; los equipos que se juntan = los que llegan por hora × las horas que pasa cada uno en el puesto (trabajo + ½ h de espera) | H23: Balanceo-FLAMA2035 › Carga M108 (jaulas) y L108 (equipos) · jaula 1,2 × 1,0 m y 28 equipos: Parametros A52:B52 | I23: Alto de la jaula
A25: R6. Recuperación y carga de CO₂ · 1 máq. · 1 turno | F25: =SUM(F26:F27) -> 1.5575 | H25: Balanceo-FLAMA2035 › Carga F109 (máq.) y G109 (turnos)
A26: Cargadora de CO₂ Firesafer FS-CO2E | B26: 1 | C26: 0.55 | D26: 0.65 | E26: 1.05 | F26: =B26*C26*D26 -> 0.3575 | H26: Catálogo Firesafer de service (FS 2026 Service Lists) | I26: Opción por función: confirmar. Alternativa FS-CO2M 0,70 × 0,55 × 0,60
A27: Jaula en espera (pulmón) | B27: 1 | C27: 1 | D27: 1.2 | E27: a confirmar | F27: =B27*C27*D27 -> 1.2 | G27: 28 equipos por jaula; los equipos que se juntan = los que llegan por hora × las horas que pasa cada uno en el puesto (trabajo + ½ h de espera) | H27: Balanceo-FLAMA2035 › Carga M109 (jaulas) y L109 (equipos) · jaula 1,2 × 1,0 m y 28 equipos: Parametros A52:B52 | I27: Alto de la jaula
A29: R7. Recuperación y carga de halogenado · 1 máq. · 1 turno | F29: =SUM(F30:F31) -> 1.2 | H29: Balanceo-FLAMA2035 › Carga F110 (máq.) y G110 (turnos)
A30: Cargadora de agente limpio Firesafer FS-FM2 | B30: 1 | C30: a confirmar | D30: a confirmar | E30: a confirmar | H30: Catálogo Firesafer de service (FS 2026 Service Lists) | I30: Sin medidas en el catálogo
A31: Jaula en espera (pulmón) | B31: 1 | C31: 1 | D31: 1.2 | E31: a confirmar | F31: =B31*C31*D31 -> 1.2 | G31: 28 equipos por jaula; los equipos que se juntan = los que llegan por hora × las horas que pasa cada uno en el puesto (trabajo + ½ h de espera) | H31: Balanceo-FLAMA2035 › Carga M110 (jaulas) y L110 (equipos) · jaula 1,2 × 1,0 m y 28 equipos: Parametros A52:B52 | I31: Alto de la jaula
A33: R8. Desarme y limpieza — recinto · 2 máq. · 2 turnos | F33: =SUM(F34:F35) -> 1.2 | H33: Balanceo-FLAMA2035 › Carga F111 (máq.) y G111 (turnos)
A34: Equipo de desarme y limpieza | B34: 2 | C34: a confirmar | D34: a confirmar | E34: a confirmar | I34: No hay cotización en la carpeta para este puesto
A35: Jaula en espera (pulmón) | B35: 1 | C35: 1 | D35: 1.2 | E35: a confirmar | F35: =B35*C35*D35 -> 1.2 | G35: 28 equipos por jaula; los equipos que se juntan = los que llegan por hora × las horas que pasa cada uno en el puesto (trabajo + ½ h de espera) | H35: Balanceo-FLAMA2035 › Carga M111 (jaulas) y L111 (equipos) · jaula 1,2 × 1,0 m y 28 equipos: Parametros A52:B52 | I35: Alto de la jaula
A37: R9. Desarme e inspección interior — zona general · 1 máq. · 1 turno | F37: =SUM(F38:F39) -> 1.2 | H37: Balanceo-FLAMA2035 › Carga F112 (máq.) y G112 (turnos)
A38: Equipo de desarme e inspección interior | B38: 1 | C38: a confirmar | D38: a confirmar | E38: a confirmar | I38: No hay cotización en la carpeta para este puesto
A39: Jaula en espera (pulmón) | B39: 1 | C39: 1 | D39: 1.2 | E39: a confirmar | F39: =B39*C39*D39 -> 1.2 | G39: 28 equipos por jaula; los equipos que se juntan = los que llegan por hora × las horas que pasa cada uno en el puesto (trabajo + ½ h de espera) | H39: Balanceo-FLAMA2035 › Carga M112 (jaulas) y L112 (equipos) · jaula 1,2 × 1,0 m y 28 equipos: Parametros A52:B52 | I39: Alto de la jaula
A41: R10. Laboratorio — Puffer y mufla · 1 máq. · 1 turno | F41: =SUM(F42:F43) -> 1.2 | H41: Balanceo-FLAMA2035 › Carga F113 (máq.) y G113 (turnos)
A42: Equipo de laboratorio | B42: 1 | C42: a confirmar | D42: a confirmar | E42: a confirmar | I42: No hay cotización en la carpeta para este puesto
A43: Jaula en espera (pulmón) | B43: 1 | C43: 1 | D43: 1.2 | E43: a confirmar | F43: =B43*C43*D43 -> 1.2 | G43: 28 equipos por jaula; los equipos que se juntan = los que llegan por hora × las horas que pasa cada uno en el puesto (trabajo + ½ h de espera) | H43: Balanceo-FLAMA2035 › Carga M113 (jaulas) y L113 (equipos) · jaula 1,2 × 1,0 m y 28 equipos: Parametros A52:B52 | I43: Alto de la jaula
A45: R11. Prueba hidráulica · 1 máq. · 2 turnos | F45: =SUM(F46:F48) -> 2.3143 | H45: Balanceo-FLAMA2035 › Carga F114 (máq.) y G114 (turnos)
A46: Bomba de PH Firesafer FS-HPT1 | B46: 1 | C46: 0.59 | D46: 0.93 | E46: 0.98 | F46: =B46*C46*D46 -> 0.5487 | H46: Catálogo Firesafer de service (FS 2026 Service Lists) | I46: Opción por función: confirmar
A47: Banco de PH de 3 puestos Firesafer FS-HPT1 | B47: 1 | C47: 0.56 | D47: 1.01 | E47: 1.2 | F47: =B47*C47*D47 -> 0.5656 | H47: Catálogo Firesafer de service (FS 2026 Service Lists) | I47: Opción por función: confirmar
A48: Jaula en espera (pulmón) | B48: 1 | C48: 1 | D48: 1.2 | E48: a confirmar | F48: =B48*C48*D48 -> 1.2 | G48: 28 equipos por jaula; los equipos que se juntan = los que llegan por hora × las horas que pasa cada uno en el puesto (trabajo + ½ h de espera) | H48: Balanceo-FLAMA2035 › Carga M114 (jaulas) y L114 (equipos) · jaula 1,2 × 1,0 m y 28 equipos: Parametros A52:B52 | I48: Alto de la jaula
A50: R12. Secado · 1 máq. · 2 turnos | F50: =SUM(F51:F52) -> 1.66 | H50: Balanceo-FLAMA2035 › Carga F115 (máq.) y G115 (turnos)
A51: Secadora de 4 bocas Firesafer FS-D4 | B51: 1 | C51: 0.46 | D51: 1 | E51: 1.1 | F51: =B51*C51*D51 -> 0.46 | H51: Catálogo Firesafer de service (FS 2026 Service Lists) | I51: Opción por función: confirmar
A52: Jaula en espera (pulmón) | B52: 1 | C52: 1 | D52: 1.2 | E52: a confirmar | F52: =B52*C52*D52 -> 1.2 | G52: 28 equipos por jaula; los equipos que se juntan = los que llegan por hora × las horas que pasa cada uno en el puesto (trabajo + ½ h de espera) | H52: Balanceo-FLAMA2035 › Carga M115 (jaulas) y L115 (equipos) · jaula 1,2 × 1,0 m y 28 equipos: Parametros A52:B52 | I52: Alto de la jaula
...

Sheet Pulmones
A1: PULMONES — qué se junta entre puestos, cómo espera y cuántos carros
A2: Columnas «Pulmones»: lo que calcula el Excel de Pulmones. Columnas «Propuesta»: 1 solo carro por tramo; mientras viaja, la bandeja que se está llenando queda en el soporte fijo del puesto que entrega (regla de Pulmones, Parametros B39). Con tandas no hace falta el carro de más.
A4: Pulmón | B4: De → a | C4: Dónde espera | D4: Máximo (u) | E4: Cómo espera | F4: Bandejas / cajones | G4: Módulos de estante | H4: Carros (Pulmones) | I4: Por qué | J4: m² (Pulmones) | K4: Carros (propuesta) | L4: m² (propuesta) | M4: Comentario
A5: MANUALES
A6: Franjas | B6: Corte de chapa — 1.er corte en franjas (guillotina 1, manuales + carros) → Corte de chapa — 2.º corte en piezas (guillotina 2, manuales + carros) | C6: Guillotina 2 (mesa elevadora 2) | D6: 90 | E6: Sobre la mesa elevadora 2 (fija), en la guillotina 2 | F6: 0 | G6: 0 | H6: 0 | I6: No se traslada en carro | J6: 0 | K6: 0 | L6: =K6*1 -> 0
A7: Desarrollos | B7: Corte de chapa — 2.º corte en piezas (guillotina 2, manuales + carros) → Marcado del cuerpo (manuales + carros) | C7: Marcado (manuales) | D7: 1505 | E7: Estante: pilas por modelo sobre bandejas | F7: 15 | G7: 3 | H7: 1 | I7: 1 carro por tramo | J7: 5.32 | K7: 1 | L7: =G7*1.44+IF(K7>0,1,0) -> 5.32
A8: Virolas | B8: Cilindrado → Soldadura longitudinal — 2,5 a 10 kg | C8: Sold. longitudinal 2,5–10 y TIG 1 kg | D8: 607 | E8: Estante: parados en bandejas, un modelo por bandeja | F8: 20 | G8: 7 | H8: 1 | I8: 1 carro por tramo | J8: 11.08 | K8: 1 | L8: =G8*1.44+IF(K8>0,1,0) -> 11.08
A9: Cuerpos soldados | B9: Soldadura longitudinal — 2,5 a 10 kg → Encastre de fondo | C9: Encastre de fondo | D9: 405 | E9: Estante: parados en bandejas, un modelo por bandeja | F9: 10 | G9: 4 | H9: 2 | I9: El que entrega no puede parar (es el cuello (soldadura longitudinal)): uno recibe mientras el otro viaja | J9: 6.76 | K9: 1 | L9: =G9*1.44+IF(K9>0,1,0) -> 6.76 | M9: Con tandas alcanza 1: la bandeja en llenado queda en el soporte fijo mientras el carro viaja
A10: Fondos | B10: Corte de disco y embutido (cúpula y fondo) → Encastre de fondo | C10: Rack junto a la prensa + encastre | D10: 6609 | E10: Rack de pallets al lado de la prensa (la tanda) + estante en el puesto con la ola de mañana | F10: 65 | G10: 2 | H10: 1 | I10: 1 carro por tramo | J10: 11.38 | K10: 1 | L10: =J10 -> 11.38
A11: Cúpulas | B11: Corte de disco y embutido (cúpula y fondo) → Soldadura del cuello a la cúpula | C11: Rack junto a la prensa + prep. de cuello | D11: 6765 | E11: Rack de pallets al lado de la prensa (la tanda) + estante en el puesto con la ola de mañana | F11: 80 | G11: 2 | H11: 1 | I11: 1 carro por tramo | J11: 12.31 | K11: 1 | L11: =J11 -> 12.31
A12: Desarrollos marcados | B12: Marcado del cuerpo (manuales + carros) → Cilindrado | C12: Cilindrado | D12: 201 | E12: Pila al alcance entre el marcado y la cilindradora (pegados) | F12: 0 | G12: 0 | H12: 0 | I12: No se traslada en carro | J12: 0 | K12: 0 | L12: =K12*1 -> 0
A13: Cúpulas con cuello | B13: Soldadura del cuello a la cúpula → Soldadura circunferencial de cúpula y fondo | C13: Sold. circunferencial | D13: 407 | E13: Estante de cajones al pie de la soldadura circunferencial | F13: 9 | G13: 1 | H13: 1 | I13: 1 carro por tramo | J13: 2.44 | K13: 1 | L13: =G13*1.44+IF(K13>0,1,0) -> 2.44
A14: Cuerpos con fondo | B14: Encastre de fondo → Bordoneado | C14: Bordoneado | D14: 315 | E14: Sin estante: el que consume no es más lento; lo que llega espera en los carros del tramo | F14: 3 | G14: 0 | H14: 2 | I14: Sin estante: ↑(3 bandejas ÷ 3) + 1 (mínimo 2) | J14: 2 | K14: 1 | L14: =K14*1 -> 1 | M14: Entra todo en 1 carro (3 bandejas): ese carro es el pulmón; la bandeja en llenado espera en el soporte fijo
A15: Cuerpos bordoneados | B15: Bordoneado → Soldadura circunferencial de cúpula y fondo | C15: Sold. circunferencial | D15: 691 | E15: Estante: parados en bandejas, un modelo por bandeja | F15: 21 | G15: 7 | H15: 1 | I15: 1 carro por tramo | J15: 11.08 | K15: 1 | L15: =G15*1.44+IF(K15>0,1,0) -> 11.08
A16: Cilindros soldados | B16: Soldadura circunferencial de cúpula y fondo → Prueba hidráulica | C16: PH (bloque PH + secado) | D16: 371 | E16: Sin estante: el que consume no es más lento; lo que llega espera en los carros del tramo | F16: 11 | G16: 0 | H16: 5 | I16: Sin estante: ↑(11 bandejas ÷ 3) + 1 | J16: 5 | K16: 5 | L16: =K16*1 -> 5 | M16: Lo que queda al cerrar el turno espera en carros estacionados (no son de tránsito). Alternativa: estante al pie del que consume
A17: Cilindros mojados | B17: Prueba hidráulica → Secado | C17: Secado | D17: 346 | E17: Sin estante: el que consume no es más lento; lo que llega espera en los carros del tramo | F17: 5 | G17: 0 | H17: 3 | I17: Sin estante: ↑(5 bandejas ÷ 3) + 1 | J17: 3 | K17: 3 | L17: =K17*1 -> 3 | M17: Lo que queda al cerrar el turno espera en carros estacionados (no son de tránsito). Alternativa: estante al pie del que consume
A18: Cilindros secos | B18: Secado → Granallado | C18: Granallado | D18: 336 | E18: Sin estante: el que consume no es más lento; lo que llega espera en los carros del tramo | F18: 6 | G18: 0 | H18: 3 | I18: Sin estante: ↑(6 bandejas ÷ 3) + 1 | J18: 3 | K18: 3 | L18: =K18*1 -> 3 | M18: Lo que queda al cerrar el turno espera en carros estacionados (no son de tránsito). Alternativa: estante al pie del que consume
A19: Cilindros granallados | B19: Granallado → Pintura en polvo + horno | C19: Pintura (carga a ganchos) | D19: 488 | E19: Estante: parados en bandejas, un modelo por bandeja | F19: 7 | G19: 2 | H19: 1 | I19: 1 carro por tramo | J19: 3.88 | K19: 1 | L19: =G19*1.44+IF(K19>0,1,0) -> 3.88
A20: Cilindros vacíos pintados | B20: Pintura en polvo + horno → Embalaje y paletizado | C20: Embalaje | D20: 421 | E20: Estante: parados en bandejas, un modelo por bandeja | F20: 5 | G20: 2 | H20: 2 | I20: El que entrega no puede parar (sale del horno de pintura): uno recibe mientras el otro viaja | J20: 3.88 | K20: 1 | L20: =G20*1.44+IF(K20>0,1,0) -> 3.88 | M20: Con tandas alcanza 1: la bandeja en llenado queda en el soporte fijo mientras el carro viaja
A21: Cilindros pintados para cargar | B21: Pintura en polvo + horno → Carga de polvo | C21: Carga de polvo | D21: 330 | E21: Estante: parados en bandejas, un modelo por bandeja | F21: 11 | G21: 4 | H21: 2 | I21: El que entrega no puede parar (sale del horno de pintura): uno recibe mientras el otro viaja | J21: 6.76 | K21: 1 | L21: =G21*1.44+IF(K21>0,1,0) -> 6.76 | M21: Con tandas alcanza 1: la bandeja en llenado queda en el soporte fijo mientras el carro viaja
A22: Cilindros cargados de polvo | B22: Carga de polvo → Ensamblaje | C22: Ensamblaje | D22: 183 | E22: Estante: parados en bandejas, un modelo por bandeja | F22: 9 | G22: 3 | H22: 1 | I22: 1 carro por tramo | J22: 5.32 | K22: 1 | L22: =G22*1.44+IF(K22>0,1,0) -> 5.32
A23: Matafuegos armados | B23: Ensamblaje → Presurización | C23: Presurización | D23: 168 | E23: Estante: parados en bandejas, un modelo por bandeja | F23: 7 | G23: 3 | H23: 1 | I23: 1 carro por tramo | J23: 5.32 | K23: 1 | L23: =G23*1.44+IF(K23>0,1,0) -> 5.32
A24: Matafuegos presurizados | B24: Presurización → Control de calidad — Ensayo de pérdidas | C24: Ensayo de pérdidas | D24: 161 | E24: Estante: parados en bandejas, un modelo por bandeja | F24: 3 | G24: 1 | H24: 1 | I24: 1 carro por tramo | J24: 2.44 | K24: 1 | L24: =G24*1.44+IF(K24>0,1,0) -> 2.44
A25: Matafuegos ensayados | B25: Control de calidad — Ensayo de pérdidas → Etiquetado | C25: Etiquetado | D25: 241 | E25: Estante: parados en bandejas, un modelo por bandeja | F25: 8 | G25: 3 | H25: 1 | I25: 1 carro por tramo | J25: 5.32 | K25: 1 | L25: =G25*1.44+IF(K25>0,1,0) -> 5.32
A26: Matafuegos etiquetados | B26: Etiquetado → Embalaje y paletizado | C26: Embalaje | D26: 161 | E26: Sin estante: el que consume no es más lento; lo que llega espera en los carros del tramo | F26: 3 | G26: 0 | H26: 2 | I26: Sin estante: ↑(3 bandejas ÷ 3) + 1 (mínimo 2) | J26: 2 | K26: 1 | L26: =K26*1 -> 1 | M26: Entra todo en 1 carro (3 bandejas): ese carro es el pulmón; la bandeja en llenado espera en el soporte fijo
A27: Total manuales | F27: =SUM(F6:F26) -> 298 | G27: =SUM(G6:G26) -> 44 | H27: =SUM(H6:H26) -> 32 | J27: =SUM(J6:J26) -> 108.29 | K27: =SUM(K6:K26) -> 27 | L27: =SUM(L6:L26) -> 106.29
A28: Supermercado de fondos y cúpulas: rack de 2 vanos × 3 niveles, 17 pallets de 12 cajones (ya contado en fondos y cúpulas)
A30: CARROS
A31: Cuerpos planos grabados | B31: Guillotinas → Cilindrado de carros | C31: 2.2 pulmón de cuerpos planos | D31: 52 | E31: Sobre la mesa móvil de la guillotina, apilados (tanda de corte) | I31: La mesa móvil rueda hasta la cilindradora de carros | J31: 7.36 | L31: =J31 -> 7.36
A32: Virolas | B32: Cilindrado → Punteo | C32: Punteo (4) | D32: 2 | E32: Piso demarcado de 1,8 × 1,2 m al pie del punteo, paradas | I32: Rodando acostadas por el piso (11 a 41 kg): no se levantan | J32: 0.49 | L32: =J32 -> 0.49
A33: Cuerpos soldados | B33: Soldadura longitudinal → Armado (7) | C33: Armado (7) | D33: 11 | E33: Piso demarcado al pie del armado (7), parados | I33: Rodando acostados hasta el virador del armado | J33: 3.07 | L33: =J33 -> 3.07
A34: Cúpulas con cupla | B34: Soldadura de cupla (6) → Armado (7) | C34: Carro canasto entre 6 y 7 | D34: 13 | E34: En el carro canasto entre la soldadura de cupla y el armado | I34: El carro canasto (pulmón y traslado a la vez, puestos pegados) | J34: 0.66 | L34: =J34 -> 0.66
A35: Cilindros cerrados | B35: Armado (7) → Accesorios (8) | C35: Accesorios (8) | D35: 1 | E35: Piso demarcado al pie de accesorios (8), parados | I35: Rodando acostados hasta la mesa de accesorios | J35: 0.25 | L35: =J35 -> 0.25
A36: Recipientes esperando la pintura | B36: PH y secado → Pintura tercerizada | C36: 11 espera del pintor | D36: 29 | E36: Espera del pintor: piso demarcado junto al portón, parados con un taco atrás | I36: Carro de manipulación hasta la espera y hasta la Master (rampa) | J36: 17.71 | L36: =J36 -> 17.71
A37: Carros pintados | B37: Recepción de pintados (12) → Carga (13) | C37: 12 recepción de pintados | D37: 29 | E37: Piso demarcado de pintados: sin ruedas, parados sobre un taco de madera | I37: Carro de manipulación hasta la carga de polvo (13); las ruedas se ponen en el montaje | J37: 17.71 | L37: =J37 -> 17.71
A38: Total carros | J38: =SUM(J31:J37) -> 47.25 | L38: =SUM(L31:L37) -> 47.25
A39: Carros: piezas de 11 a 61 kg, esperan paradas en el piso (Ø + 100 mm)² × 1,4, sin estante ni carro de tránsito.
A41: RECARGAS
A42: Jaulas en los 23 puestos | B42: dentro de cada puesto | C42: en cada puesto | D42: 238 | E42: jaulas de 28 equipos; en cada puesto se juntan los que llegan por hora × las horas que pasa cada uno ahí | F42: 25 | I42: Balanceo-FLAMA2035 › Carga filas 104 a 130 | J42: 60 | L42: =J42 -> 60
A43: Pulmón de entrada | B43: camión → recepción | C43: Pulmón de entrada | D43: 271 | E43: jaulas (½ día) | F43: 10 | I43: Balanceo-FLAMA2035 › Carga filas 104 a 130 | J43: 24 | L43: =J43 -> 24
...

Sheet Estantes y carros
A1: ESTANTES, CARROS Y CÓMO SE CARGAN
A3: 1) MUEBLES Y UNIDADES DE CARGA
A4: Elemento | B4: Frente (mm) | C4: Fondo (mm) | D4: Alto (mm) | E4: Niveles | F4: Carga máx. | G4: Cómo es por dentro | H4: Fuente
A5: Estante de carga media (1 módulo) | B5: 1200 | C5: 600 | D5: 2000 | E5: según la pieza (abajo) | F5: 300 kg por nivel | G5: Primer nivel a 100 mm del piso; el último no pasa de 1.600 mm (se carga sin escalera). Entre niveles: alto de la pieza + 100 mm para meter la mano + 40 mm de la bandeja. 1 bandeja o 3 cajones por nivel. | H5: PULMONES-FLAMA2035 › Parametros B7:B13
A6: Bandeja metálica | B6: 1200 | C6: 600 | D6: 40 | E6: — | F6: 150 kg | G6: Chapa plegada de 2 mm con borde de 30 mm. Rueda del carro al estante sobre carriles de rodillos. Un solo modelo por bandeja. | H6: PULMONES-FLAMA2035 › Parametros B19:B22
A7: Cajón plástico | B7: 600 | C7: 400 | D7: 300 | E7: — | F7: 20 kg con el cajón | G7: Interior 560 × 360 × 280 mm (pared y fondo de 20 mm). Fondos y cúpulas en columnas anidadas con 5 mm de luz. | H7: PULMONES-FLAMA2035 › Parametros B23:B30
A8: Carro porta-bandejas (tránsito) | B8: 1300 | C8: 700 | D8: a confirmar | E8: 3 | F8: 450 kg (3 × 150) | G8: 3 niveles a la misma altura que los 3 primeros del estante: la bandeja pasa deslizando del carro al estante. | H8: PULMONES-FLAMA2035 › Parametros B37, B42
A9: Carro de 12 cajones (tránsito) | B9: 1300 | C9: 700 | D9: a confirmar | E9: 4 | F9: 12 cajones | G9: 4 niveles de 3 cajones de 600 × 400, a la altura de los niveles del estante de cajones (100 / 500 / 900 / 1.300 mm). | H9: PULMONES-FLAMA2035 › Parametros B38
A10: Soporte fijo junto al puesto que entrega | B10: 1200 | C10: 600 | D10: a confirmar | E10: 1 | F10: 1 bandeja | G10: Donde queda la bandeja que se está llenando mientras el carro viaja. | H10: PULMONES-FLAMA2035 › Parametros B39
A11: Rack selectivo (supermercado de fondos y cúpulas) | B11: 2700 | C11: 1200 | D11: a confirmar | E11: 3 | F11: 3 pallets por nivel | G11: Vano de 2,7 m, 3 pallets de 800 de frente por nivel. Primer nivel a 400 mm (picking a mano entre 0,55 y 1,45 m); arriba, reserva. | H11: PULMONES-FLAMA2035 › Parametros B53:B58
A12: Pallet de cajones (fondos o cúpulas) | B12: 1200 | C12: 800 | D12: 1045 | E12: 3 capas | F12: 12 cajones | G12: 4 cajones por capa (2 × 2) y 3 capas. Un solo modelo por pallet. | H12: PULMONES-FLAMA2035 › Parametros B53
A13: Jaula de recargas | B13: 1200 | C13: 1000 | D13: a confirmar | E13: apilada a 2 | F13: 28 equipos | G13: Paletizable. | H13: Balanceo-FLAMA2035 › Parametros (U_JAULA) y Carga A131
A15: 2) CÓMO SE CARGA CADA PIEZA (por modelo)
A16: Pieza y unidad de carga | B16: Modelo | C16: Cómo va | D16: Piezas por bandeja / cajón | E16: Peso (kg) | F16: Alto que ocupa (mm) | G16: Altura de cada nivel del estante (mm) | H16: Por módulo de estante | I16: Por carro | J16: A confirmar
A17: Desarrollo — pila sobre bandeja | B17: 1 kg | C17: 1 pila de 254 desarrollos (chapa de 0,9 mm) | D17: 254 | E17: 149.9 | F17: 229 | G17: 5 niveles: 100 / 469 / 838 / 1207 / 1576 | H17: 1270 | I17: 762
B18: 2,5 kg | C18: 1 pila de 147 desarrollos (chapa de 1,25 mm) | D18: 147 | E18: 149.9 | F18: 184 | G18: 5 niveles: 100 / 424 / 748 / 1072 / 1396 | H18: 735 | I18: 441
B19: 5 kg | C19: 1 pila de 76 desarrollos (chapa de 1,6 mm) | D19: 76 | E19: 149.7 | F19: 122 | G19: 6 niveles: 100 / 362 / 624 / 886 / 1148 / 1410 | H19: 456 | I19: 228
B20: 10 kg | C20: 1 pila de 34 desarrollos (chapa de 2,0 mm) | D20: 34 | E20: 148.9 | F20: 68 | G20: 8 niveles: 100 / 308 / 516 / 724 / 932 / 1140 / 1348 / 1556 | H20: 272 | I20: 102
A21: Virola o cuerpo — parado sobre bandeja | B21: 1 kg | C21: parados en 15 filas × 7 = 105 (Ø 76,2 mm) | D21: 105 | E21: 62 | F21: 297.5 | G21: 4 niveles: 100 / 538 / 976 / 1414 | H21: 420 | I21: 315
B22: 2,5 kg | C22: parados en 9 filas × 4 = 36 (Ø 124,0 mm) | D22: 36 | E22: 36.7 | F22: 333 | G22: 4 niveles: 100 / 573 / 1046 / 1519 | H22: 144 | I22: 108
B23: 5 kg | C23: parados en 7 filas × 3 = 21 (Ø 153,0 mm) | D23: 21 | E23: 41.4 | F23: 414 | G23: 3 niveles: 100 / 654 / 1208 | H23: 63 | I23: 63
B24: 10 kg | C24: parados en 6 filas × 3 = 18 (Ø 181,5 mm) | D24: 18 | E24: 78.8 | F24: 582 | G24: 3 niveles: 100 / 822 / 1544 | H24: 54 | I24: 54
A25: Cilindro — parado sobre bandeja | B25: 1 kg | C25: parados en 15 filas × 7 = 105 (Ø 76,2 mm) | D25: 105 | E25: 74.5 | F25: 297.5 | G25: 4 niveles: 100 / 538 / 976 / 1414 | H25: 420 | I25: 315
B26: 2,5 kg | C26: parados en 9 filas × 4 = 36 (Ø 124,0 mm) | D26: 36 | E26: 48.6 | F26: 333 | G26: 4 niveles: 100 / 573 / 1046 / 1519 | H26: 144 | I26: 108
B27: 5 kg | C27: parados en 7 filas × 3 = 21 (Ø 153,0 mm) | D27: 21 | E27: 54.6 | F27: 414 | G27: 3 niveles: 100 / 654 / 1208 | H27: 63 | I27: 63
B28: 10 kg | C28: parados en 6 filas × 3 = 18 (Ø 181,5 mm) | D28: 18 | E28: 98.6 | F28: 582 | G28: 3 niveles: 100 / 822 / 1544 | H28: 54 | I28: 54
A29: Matafuego — parado sobre bandeja | B29: 1 kg | C29: parados, 72 (por peso: entran 15 × 7 = 105) | D29: 72 | E29: 149.8 | F29: 390 | G29: 3 niveles: 100 / 630 / 1160 | H29: 216 | I29: 216
B30: 2,5 kg | C30: parados, 34 (por peso: entran 9 × 4 = 36) | D30: 34 | E30: 146.2 | F30: 415 | G30: 3 niveles: 100 / 655 / 1210 | H30: 102 | I30: 102
B31: 5 kg | C31: parados, 18 (por peso: entran 7 × 3 = 21) | D31: 18 | E31: 145.8 | F31: 495 | G31: 3 niveles: 100 / 735 / 1370 | H31: 54 | I31: 54
B32: 10 kg | C32: parados, 9 (por peso: entran 6 × 3 = 18) | D32: 9 | E32: 143.5 | F32: 665 | G32: 2 niveles: 100 / 905 | H32: 18 | I32: 27 | J32: En el carro entran 3 bandejas, pero en el estante solo 2 niveles quedan bajo 1,6 m
A33: Fondo — en cajón | B33: 1 kg | C33: 6 × 4 columnas de 12 piezas anidadas | D33: 288 | E33: 17.4 | F33: 300 | G33: 4 niveles: 100 / 500 / 900 / 1300 | H33: 3456 | I33: 3456
B34: 2,5 kg | C34: 4 × 2 columnas de 11 piezas anidadas | D34: 88 | E34: 19.7 | F34: 300 | G34: 4 niveles: 100 / 500 / 900 / 1300 | H34: 1056 | I34: 1056
B35: 5 kg | C35: 3 × 2 columnas de 8 piezas anidadas | D35: 48 | E35: 19.3 | F35: 300 | G35: 4 niveles: 100 / 500 / 900 / 1300 | H35: 576 | I35: 576
B36: 10 kg | C36: 3 × 1 columnas de 9 piezas anidadas | D36: 27 | E36: 18.4 | F36: 300 | G36: 4 niveles: 100 / 500 / 900 / 1300 | H36: 324 | I36: 324
A37: Cúpula — en cajón | B37: 1 kg | C37: 6 × 4 columnas de 12 piezas anidadas | D37: 288 | E37: 14.5 | F37: 300 | G37: 4 niveles: 100 / 500 / 900 / 1300 | H37: 3456 | I37: 3456
B38: 2,5 kg | C38: 4 × 2 columnas de 10 piezas anidadas | D38: 80 | E38: 19.8 | F38: 300 | G38: 4 niveles: 100 / 500 / 900 / 1300 | H38: 960 | I38: 960
B39: 5 kg | C39: 3 × 2 columnas de 6 piezas anidadas | D39: 36 | E39: 18.1 | F39: 300 | G39: 4 niveles: 100 / 500 / 900 / 1300 | H39: 432 | I39: 432
B40: 10 kg | C40: 3 × 1 columnas de 7 piezas anidadas | D40: 21 | E40: 17.9 | F40: 300 | G40: 4 niveles: 100 / 500 / 900 / 1300 | H40: 252 | I40: 252
A41: Cúpula con cuello — en cajón | B41: 1 kg | C41: sueltas en el cajón (Pulmones, Unidades fila 48; límite 20 kg) | D41: 100 | E41: 8 | F41: 300 | G41: 4 niveles: 100 / 500 / 900 / 1300 | H41: 1200 | I41: 1200
B42: 2,5 kg | C42: sueltas en el cajón (Pulmones, Unidades fila 48; límite 20 kg) | D42: 40 | E42: 13.5 | F42: 300 | G42: 4 niveles: 100 / 500 / 900 / 1300 | H42: 480 | I42: 480
...
